Workbook

Sheet Cstoumer Names
A1: Customer ID | B1: name
A2: Id1 | B2: Hawks, | C2: Ms. | D2: Kelly
A3: Id2 | B3: Lehner, | C3: Mr. | D3: Matthew | E3: D
A4: Id3 | B4: Lu, | C4: Mr. | D4: Phil
A5: Id4 | B5: Osborne, | C5: Ms. | D5: Kelsey
A6: Id5 | B6: Kadala, | C6: Ms. | D6: Kristyn
A7: Id6 | B7: Baker, | C7: Mr. | D7: Russell | E7: B.
A8: Id7 | B8: Macpherson, | C8: Mr. | D8: Scott
A9: Id8 | B9: Hallman, | C9: Mr. | D9: Stephen
A10: Id9 | B10: Moran, | C10: Mr. | D10: Patrick | E10: R.
A11: Id10 | B11: Benner, | C11: Ms. | D11: Brooke | E11: N.
A12: Id11 | B12: Fierro | C12: Vargas, | D12: Ms. | E12: Paola | F12: Andrea
A13: Id12 | B13: Franz, | C13: Mr. | D13: David
A14: Id13 | B14: Foster, | C14: Mr. | D14: Wade
A15: Id14 | B15: Tenorio, | C15: Mr. | D15: Franklin
A16: Id15 | B16: Rios, | C16: Ms. | D16: Leilani | E16: M.
A17: Id16 | B17: Viau-Dupuis, | C17: Mr. | D17: Philippe
A18: Id17 | B18: Cronin, | C18: Ms. | D18: Jennifer | E18: A.
A19: Id18 | B19: Noordstar, | C19: Ms. | D19: Christina | E19: M.
A20: Id19 | B20: Boudalia, | C20: Mr. | D20: Said | E20: Sr.
A21: Id20 | B21: Flor, | C21: Mr. | D21: John
A22: Id21 | B22: Fennon, | C22: Mr. | D22: Myles
A23: Id22 | B23: Hribar, | C23: Ms. | D23: Madelyn | E23: C
A24: Id23 | B24: Tassello, | C24: Ms. | D24: Nicole
A25: Id24 | B25: Mauricette, | C25: Mr. | D25: Eric | E25: A.
A26: Id25 | B26: Garcia, | C26: Mr. | D26: Emiliano | E26: I.
A27: Id26 | B27: Airoldi, | C27: Mr. | D27: Adam
A28: Id27 | B28: Cater-Cyker, | C28: Mr. | D28: Zach
A29: Id28 | B29: Hamm, | C29: Ms. | D29: Stephanie | E29: W.
A30: Id29 | B30: Cox, | C30: Mr. | D30: Stephen
A31: Id30 | B31: Sachrajda, | C31: Ms. | D31: Natalie
A32: Id31 | B32: Gareri, | C32: Ms. | D32: Nicole | E32: J.
A33: Id32 | B33: Welch, | C33: Mr. | D33: Jefferson | E33: D
A34: Id33 | B34: Prindiville, | C34: Mr. | D34: Brendan | E34: D.
A35: Id34 | B35: Kincaid, | C35: Ms. | D35: Courtney
A36: Id35 | B36: Bruestle, | C36: Ms. | D36: Sydney | E36: L.
A37: Id36 | B37: Lachance, | C37: Mr. | D37: Julien
A38: Id37 | B38: Eason, | C38: Mr. | D38: Ryan | E38: M
A39: Id38 | B39: Grummon, | C39: Ms. | D39: Anna | E39: H.
A40: Id39 | B40: Vanwechel, | C40: Ms. | D40: Samantha
...

Sheet Medical Examination
A1: Customer ID | B1: BMI | C1: HBA1C | D1: Heart Issues | E1: Any Transplants | F1: Cancer history | G1: NumberOfMajorSurgeries | H1: smoker | I1: BMI | J1: HBA1C
A2: Id1 | B2: 47.41 | C2: 7.47 | D2: No | E2: No | F2: No | G2: 0 | H2: Yes | I2: =IF(B2<18.5,"Under Weight",IF(B2<25,"Normal Weight",IF(B2<30,"Over weight","Obesity"))) -> Obesity | J2: =IF(C2<5.7,"Normal",IF(C2<6.5,"Prediabetes","Diabetes")) -> Diabetes
A3: Id2 | B3: 30.36 | C3: 5.77 | D3: No | E3: No | F3: No | G3: 0 | H3: Yes | I3: =IF(B3<18.5,"Under Weight",IF(B3<25,"Normal Weight",IF(B3<30,"Over weight","Obesity"))) -> Obesity | J3: =IF(C3<5.7,"Normal",IF(C3<6.5,"Prediabetes","Diabetes")) -> Prediabetes
A4: Id3 | B4: 34.485 | C4: 11.87 | D4: Yes | E4: No | F4: No | G4: 1 | H4: Yes | I4: =IF(B4<18.5,"Under Weight",IF(B4<25,"Normal Weight",IF(B4<30,"Over weight","Obesity"))) -> Obesity | J4: =IF(C4<5.7,"Normal",IF(C4<6.5,"Prediabetes","Diabetes")) -> Diabetes
A5: Id4 | B5: 38.095 | C5: 6.05 | D5: No | E5: No | F5: No | G5: 0 | H5: Yes | I5: =IF(B5<18.5,"Under Weight",IF(B5<25,"Normal Weight",IF(B5<30,"Over weight","Obesity"))) -> Obesity | J5: =IF(C5<5.7,"Normal",IF(C5<6.5,"Prediabetes","Diabetes")) -> Prediabetes
A6: Id5 | B6: 35.53 | C6: 5.45 | D6: No | E6: No | F6: No | G6: 0 | H6: Yes | I6: =IF(B6<18.5,"Under Weight",IF(B6<25,"Normal Weight",IF(B6<30,"Over weight","Obesity"))) -> Obesity | J6: =IF(C6<5.7,"Normal",IF(C6<6.5,"Prediabetes","Diabetes")) -> Normal
A7: Id6 | B7: 32.8 | C7: 6.59 | D7: No | E7: No | F7: No | G7: 0 | H7: Yes | I7: =IF(B7<18.5,"Under Weight",IF(B7<25,"Normal Weight",IF(B7<30,"Over weight","Obesity"))) -> Obesity | J7: =IF(C7<5.7,"Normal",IF(C7<6.5,"Prediabetes","Diabetes")) -> Diabetes
A8: Id7 | B8: 36.4 | C8: 6.07 | D8: No | E8: No | F8: No | G8: 0 | H8: Yes | I8: =IF(B8<18.5,"Under Weight",IF(B8<25,"Normal Weight",IF(B8<30,"Over weight","Obesity"))) -> Obesity | J8: =IF(C8<5.7,"Normal",IF(C8<6.5,"Prediabetes","Diabetes")) -> Prediabetes
A9: Id8 | B9: 36.96 | C9: 7.93 | D9: No | E9: No | F9: No | G9: 1 | H9: Yes | I9: =IF(B9<18.5,"Under Weight",IF(B9<25,"Normal Weight",IF(B9<30,"Over weight","Obesity"))) -> Obesity | J9: =IF(C9<5.7,"Normal",IF(C9<6.5,"Prediabetes","Diabetes")) -> Diabetes
A10: Id9 | B10: 41.14 | C10: 9.58 | D10: Yes | E10: No | F10: Yes | G10: 1 | H10: Yes | I10: =IF(B10<18.5,"Under Weight",IF(B10<25,"Normal Weight",IF(B10<30,"Over weight","Obesity"))) -> Obesity | J10: =IF(C10<5.7,"Normal",IF(C10<6.5,"Prediabetes","Diabetes")) -> Diabetes
A11: Id10 | B11: 38.06 | C11: 10.79 | D11: No | E11: No | F11: No | G11: 0 | H11: Yes | I11: =IF(B11<18.5,"Under Weight",IF(B11<25,"Normal Weight",IF(B11<30,"Over weight","Obesity"))) -> Obesity | J11: =IF(C11<5.7,"Normal",IF(C11<6.5,"Prediabetes","Diabetes")) -> Diabetes
A12: Id11 | B12: 37.7 | C12: 5.96 | D12: Yes | E12: No | F12: No | G12: 1 | H12: Yes | I12: =IF(B12<18.5,"Under Weight",IF(B12<25,"Normal Weight",IF(B12<30,"Over weight","Obesity"))) -> Obesity | J12: =IF(C12<5.7,"Normal",IF(C12<6.5,"Prediabetes","Diabetes")) -> Prediabetes
A13: Id12 | B13: 42.13 | C13: 11.9 | D13: No | E13: No | F13: No | G13: 0 | H13: Yes | I13: =IF(B13<18.5,"Under Weight",IF(B13<25,"Normal Weight",IF(B13<30,"Over weight","Obesity"))) -> Obesity | J13: =IF(C13<5.7,"Normal",IF(C13<6.5,"Prediabetes","Diabetes")) -> Diabetes
... A101: Id100 | B101: 48.2 | C101: 4.84 | D101: No | E101: No | F101: No | G101: 0 | H101: Yes | I101: =IF(B101<18.5,"Under Weight",IF(B101<25,"Normal Weight",IF(B101<30,"Over weight","Obesity"))) -> Obesity | J101: =IF(C101<5.7,"Normal",IF(C101<6.5,"Prediabetes","Diabetes")) -> Normal
A102: Id101 | B102: 35.75 | C102: Yes | D102: Yes | E102: No | F102: No | G102: 0 | H102: Yes | I102: =IF(B102<18.5,"Under Weight",IF(B102<25,"Normal Weight",IF(B102<30,"Over weight","Obesity"))) -> Obesity | J102: =IF(C102<5.7,"Normal",IF(C102<6.5,"Prediabetes","Diabetes")) -> Diabetes
A103: Id102 | B103: 53.81 | C103: 8.77 | D103: Yes | E103: No | F103: No | G103: 0 | H103: Yes | I103: =IF(B103<18.5,"Under Weight",IF(B103<25,"Normal Weight",IF(B103<30,"Over weight","Obesity"))) -> Obesity | J103: =IF(C103<5.7,"Normal",IF(C103<6.5,"Prediabetes","Diabetes")) -> Diabetes
A104: Id103 | B104: 49.48 | C104: 4.96 | D104: No | E104: No | F104: Yes | G104: 1 | H104: Yes | I104: =IF(B104<18.5,"Under Weight",IF(B104<25,"Normal Weight",IF(B104<30,"Over weight","Obesity"))) -> Obesity | J104: =IF(C104<5.7,"Normal",IF(C104<6.5,"Prediabetes","Diabetes")) -> Normal
A105: Id104 | B105: 34.1 | C105: 4.43 | D105: Yes | E105: No | F105: No | G105: 0 | H105: Yes | I105: =IF(B105<18.5,"Under Weight",IF(B105<25,"Normal Weight",IF(B105<30,"Over weight","Obesity"))) -> Obesity | J105: =IF(C105<5.7,"Normal",IF(C105<6.5,"Prediabetes","Diabetes")) -> Normal
A106: Id105 | B106: 35.3 | C106: 5.82 | D106: Yes | E106: No | F106: Yes | G106: 1 | H106: Yes | I106: =IF(B106<18.5,"Under Weight",IF(B106<25,"Normal Weight",IF(B106<30,"Over weight","Obesity"))) -> Obesity | J106: =IF(C106<5.7,"Normal",IF(C106<6.5,"Prediabetes","Diabetes")) -> Prediabetes
A107: Id106 | B107: 43.83 | C107: 6.03 | D107: Yes | E107: No | F107: No | G107: 1 | H107: Yes | I107: =IF(B107<18.5,"Under Weight",IF(B107<25,"Normal Weight",IF(B107<30,"Over weight","Obesity"))) -> Obesity | J107: =IF(C107<5.7,"Normal",IF(C107<6.5,"Prediabetes","Diabetes")) -> Prediabetes
A108: Id107 | B108: 50.07 | C108: 9.27 | D108: No | E108: No | F108: No | G108: 0 | H108: Yes | I108: =IF(B108<18.5,"Under Weight",IF(B108<25,"Normal Weight",IF(B108<30,"Over weight","Obesity"))) -> Obesity | J108: =IF(C108<5.7,"Normal",IF(C108<6.5,"Prediabetes","Diabetes")) -> Diabetes
A109: Id108 | B109: 32.775 | C109: 5.53 | D109: No | E109: No | F109: No | G109: 0 | H109: Yes | I109: =IF(B109<18.5,"Under Weight",IF(B109<25,"Normal Weight",IF(B109<30,"Over weight","Obesity"))) -> Obesity | J109: =IF(C109<5.7,"Normal",IF(C109<6.5,"Prediabetes","Diabetes")) -> Normal
A110: Id109 | B110: 34.105 | C110: 5.07 | D110: No | E110: No | F110: No | G110: 1 | H110: Yes | I110: =IF(B110<18.5,"Under Weight",IF(B110<25,"Normal Weight",IF(B110<30,"Over weight","Obesity"))) -> Obesity | J110: =IF(C110<5.7,"Normal",IF(C110<6.5,"Prediabetes","Diabetes")) -> Normal
A111: Id110 | B111: 48.93 | C111: 11.17 | D111: Yes | E111: No | F111: No | G111: 1 | H111: Yes | I111: =IF(B111<18.5,"Under Weight",IF(B111<25,"Normal Weight",IF(B111<30,"Over weight","Obesity"))) -> Obesity | J111: =IF(C111<5.7,"Normal",IF(C111<6.5,"Prediabetes","Diabetes")) -> Diabetes
A112: Id111 | B112: 37.07 | C112: 6.14 | D112: Yes | E112: No | F112: No | G112: 0 | H112: Yes | I112: =IF(B112<18.5,"Under Weight",IF(B112<25,"Normal Weight",IF(B112<30,"Over weight","Obesity"))) -> Obesity | J112: =IF(C112<5.7,"Normal",IF(C112<6.5,"Prediabetes","Diabetes")) -> Prediabetes
A113: Id112 | B113: 51.51 | C113: 6.26 | D113: Yes | E113: No | F113: Yes | G113: 1 | H113: Yes | I113: =IF(B113<18.5,"Under Weight",IF(B113<25,"Normal Weight",IF(B113<30,"Over weight","Obesity"))) -> Obesity | J113: =IF(C113<5.7,"Normal",IF(C113<6.5,"Prediabetes","Diabetes")) -> Prediabetes
A114: Id113 | B114: 34.8 | C114: 4.72 | D114: Yes | E114: No | F114: No | G114: 0 | H114: Yes | I114: =IF(B114<18.5,"Under Weight",IF(B114<25,"Normal Weight",IF(B114<30,"Over weight","Obesity"))) -> Obesity | J114: =IF(C114<5.7,"Normal",IF(C114<6.5,"Prediabetes","Diabetes")) -> Normal
... A167: Id166 | B167: 37.87 | C167: 4.29 | D167: Yes | E167: No | F167: Yes | G167: 1 | H167: Yes | I167: =IF(B167<18.5,"Under Weight",IF(B167<25,"Normal Weight",IF(B167<30,"Over weight","Obesity"))) -> Obesity | J167: =IF(C167<5.7,"Normal",IF(C167<6.5,"Prediabetes","Diabetes")) -> Normal
A168: Id167 | B168: 40.61 | C168: Yes | D168: Yes | E168: No | F168: No | G168: 1 | H168: Yes | I168: =IF(B168<18.5,"Under Weight",IF(B168<25,"Normal Weight",IF(B168<30,"Over weight","Obesity"))) -> Obesity | J168: =IF(C168<5.7,"Normal",IF(C168<6.5,"Prediabetes","Diabetes")) -> Diabetes
A169: Id168 | B169: 30.78 | C169: 4.67 | D169: Yes | E169: No | F169: No | G169: 0 | H169: Yes | I169: =IF(B169<18.5,"Under Weight",IF(B169<25,"Normal Weight",IF(B169<30,"Over weight","Obesity"))) -> Obesity | J169: =IF(C169<5.7,"Normal",IF(C169<6.5,"Prediabetes","Diabetes")) -> Normal
A170: Id169 | B170: 49.49 | C170: 4.5 | D170: No | E170: No | F170: No | G170: 0 | H170: Yes | I170: =IF(B170<18.5,"Under Weight",IF(B170<25,"Normal Weight",IF(B170<30,"Over weight","Obesity"))) -> Obesity | J170: =IF(C170<5.7,"Normal",IF(C170<6.5,"Prediabetes","Diabetes")) -> Normal
A171: Id170 | B171: 37.62 | C171: 6.32 | D171: Yes | E171: yes | F171: No | G171: 1 | H171: Yes | I171: =IF(B171<18.5,"Under Weight",IF(B171<25,"Normal Weight",IF(B171<30,"Over weight","Obesity"))) -> Obesity | J171: =IF(C171<5.7,"Normal",IF(C171<6.5,"Prediabetes","Diabetes")) -> Prediabetes
A172: Id171 | B172: 36.08 | C172: 6.1 | D172: Yes | E172: No | F172: No | G172: 1 | H172: Yes | I172: =IF(B172<18.5,"Under Weight",IF(B172<25,"Normal Weight",IF(B172<30,"Over weight","Obesity"))) -> Obesity | J172: =IF(C172<5.7,"Normal",IF(C172<6.5,"Prediabetes","Diabetes")) -> Prediabetes
A173: Id172 | B173: 33.5 | C173: 5.4 | D173: No | E173: No | F173: No | G173: 0 | H173: Yes | I173: =IF(B173<18.5,"Under Weight",IF(B173<25,"Normal Weight",IF(B173<30,"Over weight","Obesity"))) -> Obesity | J173: =IF(C173<5.7,"Normal",IF(C173<6.5,"Prediabetes","Diabetes")) -> Normal
A174: Id173 | B174: 47.46 | C174: 6.24 | D174: Yes | E174: No | F174: No | G174: 1 | H174: Yes | I174: =IF(B174<18.5,"Under Weight",IF(B174<25,"Normal Weight",IF(B174<30,"Over weight","Obesity"))) -> Obesity | J174: =IF(C174<5.7,"Normal",IF(C174<6.5,"Prediabetes","Diabetes")) -> Prediabetes
A175: Id174 | B175: 49.24 | C175: 4.45 | D175: No | E175: No | F175: No | G175: 0 | H175: Yes | I175: =IF(B175<18.5,"Under Weight",IF(B175<25,"Normal Weight",IF(B175<30,"Over weight","Obesity"))) -> Obesity | J175: =IF(C175<5.7,"Normal",IF(C175<6.5,"Prediabetes","Diabetes")) -> Normal
A176: Id175 | B176: 54.4 | C176: 5.22 | D176: No | E176: No | F176: No | G176: 1 | H176: Yes | I176: =IF(B176<18.5,"Under Weight",IF(B176<25,"Normal Weight",IF(B176<30,"Over weight","Obesity"))) -> Obesity | J176: =IF(C176<5.7,"Normal",IF(C176<6.5,"Prediabetes","Diabetes")) -> Normal
A177: Id176 | B177: 35.53 | C177: 4.61 | D177: No | E177: No | F177: No | G177: 1 | H177: Yes | I177: =IF(B177<18.5,"Under Weight",IF(B177<25,"Normal Weight",IF(B177<30,"Over weight","Obesity"))) -> Obesity | J177: =IF(C177<5.7,"Normal",IF(C177<6.5,"Prediabetes","Diabetes")) -> Normal
A178: Id177 | B178: 39.73 | C178: 6.24 | D178: No | E178: No | F178: No | G178: 0 | H178: Yes | I178: =IF(B178<18.5,"Under Weight",IF(B178<25,"Normal Weight",IF(B178<30,"Over weight","Obesity"))) -> Obesity | J178: =IF(C178<5.7,"Normal",IF(C178<6.5,"Prediabetes","Diabetes")) -> Prediabetes
A179: Id178 | B179: 35.68 | C179: 10.04 | D179: No | E179: No | F179: No | G179: 0 | H179: Yes | I179: =IF(B179<18.5,"Under Weight",IF(B179<25,"Normal Weight",IF(B179<30,"Over weight","Obesity"))) -> Obesity | J179: =IF(C179<5.7,"Normal",IF(C179<6.5,"Prediabetes","Diabetes")) -> Diabetes
...

Sheet Hospitalisation Detailes
A1: Customer ID | B1: year | C1: month | D1: date | E1: children | F1: charges | G1: Hospital tier | H1: City tier | I1: State ID | J1: YYY-MM-DD
A2: Id2335 | B2: 1992 | C2: Jul | D2: 9 | E2: 0 | F2: 563.84 | G2: tier - 2 | H2: tier - 3 | I2: R1013 | J2: =DATE(B2,MONTH(1&C2),D2) -> 33794
A3: Id2334 | B3: 1992 | C3: Nov | D3: 30 | E3: 0 | F3: 570.62 | G3: tier - 2 | H3: tier - 1 | I3: R1013 | J3: =DATE(B3,MONTH(1&C3),D3) -> 33938
A4: Id2333 | B4: 1993 | C4: Jun | D4: 30 | E4: 0 | F4: 600 | G4: tier - 2 | H4: tier - 1 | I4: R1013 | J4: =DATE(B4,MONTH(1&C4),D4) -> 34150
A5: Id2332 | B5: 1992 | C5: Sep | D5: 13 | E5: 0 | F5: 604.54 | G5: tier - 3 | H5: tier - 3 | I5: R1013 | J5: =DATE(B5,MONTH(1&C5),D5) -> 33860
A6: Id2331 | B6: 1998 | C6: Jul | D6: 27 | E6: 0 | F6: 637.26 | G6: tier - 3 | H6: tier - 3 | I6: R1013 | J6: =DATE(B6,MONTH(1&C6),D6) -> 36003
A7: Id2330 | B7: 2001 | C7: Nov | D7: 20 | E7: 0 | F7: 646.14 | G7: tier - 3 | H7: tier - 3 | I7: R1012 | J7: =DATE(B7,MONTH(1&C7),D7) -> 37215
A8: Id2329 | B8: 1993 | C8: Jun | D8: 1 | E8: 0 | F8: 650 | G8: tier - 3 | H8: tier - 3 | I8: R1013 | J8: =DATE(B8,MONTH(1&C8),D8) -> 34121
A9: Id2328 | B9: 1995 | C9: Jul | D9: 4 | E9: 0 | F9: 650 | G9: tier - 3 | H9: tier - 3 | I9: R1013 | J9: =DATE(B9,MONTH(1&C9),D9) -> 34884
A10: Id2327 | B10: 2002 | C10: Nov | D10: 29 | E10: 0 | F10: 668 | G10: tier - 3 | H10: tier - 2 | I10: R1012 | J10: =DATE(B10,MONTH(1&C10),D10) -> 37589
A11: Id2326 | B11: 1997 | C11: Nov | D11: 9 | E11: 0 | F11: 670 | G11: tier - 3 | H11: tier - 3 | I11: R1013 | J11: =DATE(B11,MONTH(1&C11),D11) -> 35743
A12: Id2325 | B12: 2001 | C12: Sep | D12: 12 | E12: 0 | F12: 687.54 | G12: tier - 3 | H12: tier - 2 | I12: R1013 | J12: =DATE(B12,MONTH(1&C12),D12) -> 37146
A13: Id2324 | B13: 1999 | C13: Dec | D13: 26 | E13: 0 | F13: 700 | G13: tier - 2 | H13: tier - 3 | I13: R1013 | J13: =DATE(B13,MONTH(1&C13),D13) -> 36520
... A1050: Id1290 | B1050: 1977 | C1050: Jul | D1050: 26 | E1050: 2 | F1050: 8527.53 | G1050: tier - 2 | H1050: tier - 2 | I1050: R1013 | J1050: =DATE(B1050,MONTH(1&C1050),D1050) -> 28332
A1051: Id1289 | B1051: ? | C1051: Jul | D1051: 24 | E1051: 0 | F1051: 8534.67 | G1051: tier - 2 | H1051: tier - 3 | I1051: R1024 | J1051: =DATE(B1051,MONTH(1&C1051),D1051) -> #VALUE!
A1052: Id1288 | B1052: 1981 | C1052: Dec | D1052: 27 | E1052: 3 | F1052: 8538.29 | G1052: tier - 2 | H1052: tier - 3 | I1052: R1024 | J1052: =DATE(B1052,MONTH(1&C1052),D1052) -> 29947
A1053: Id1287 | B1053: 1975 | C1053: Nov | D1053: 6 | E1053: 1 | F1053: 8539.67 | G1053: tier - 2 | H1053: tier - 3 | I1053: R1011 | J1053: =DATE(B1053,MONTH(1&C1053),D1053) -> 27704
A1054: Id1286 | B1054: ? | C1054: Dec | D1054: 12 | E1054: 1 | F1054: 8547.69 | G1054: tier - 2 | H1054: tier - 1 | I1054: R1013 | J1054: =DATE(B1054,MONTH(1&C1054),D1054) -> #VALUE!
A1055: Id1285 | B1055: 1975 | C1055: Aug | D1055: 6 | E1055: 1 | F1055: 8551.35 | G1055: tier - 2 | H1055: tier - 2 | I1055: R1011 | J1055: =DATE(B1055,MONTH(1&C1055),D1055) -> 27612
A1056: Id1284 | B1056: 1975 | C1056: Aug | D1056: 21 | E1056: 1 | F1056: 8556.91 | G1056: tier - 2 | H1056: tier - 1 | I1056: R1011 | J1056: =DATE(B1056,MONTH(1&C1056),D1056) -> 27627
A1057: Id1283 | B1057: 1988 | C1057: Sep | D1057: 21 | E1057: 3 | F1057: 8567.25 | G1057: tier - 2 | H1057: tier - 1 | I1057: R1012 | J1057: =DATE(B1057,MONTH(1&C1057),D1057) -> 32407
A1058: Id1282 | B1058: 1975 | C1058: Sep | D1058: 26 | E1058: 1 | F1058: 8569.86 | G1058: tier - 2 | H1058: tier - 3 | I1058: R1013 | J1058: =DATE(B1058,MONTH(1&C1058),D1058) -> 27663
A1059: Id1281 | B1059: 1982 | C1059: Dec | D1059: 6 | E1059: 3 | F1059: 8572.04 | G1059: tier - 2 | H1059: tier - 2 | I1059: R1021 | J1059: =DATE(B1059,MONTH(1&C1059),D1059) -> 30291
A1060: Id1280 | B1060: 1987 | C1060: Nov | D1060: 11 | E1060: 3 | F1060: 8573.3 | G1060: tier - 2 | H1060: tier - 2 | I1060: R1021 | J1060: =DATE(B1060,MONTH(1&C1060),D1060) -> 32092
A1061: Id1279 | B1061: 1983 | C1061: Dec | D1061: 30 | E1061: 5 | F1061: 8582.3 | G1061: tier - 2 | H1061: tier - 1 | I1061: R1013 | J1061: =DATE(B1061,MONTH(1&C1061),D1061) -> 30680
A1062: Id1278 | B1062: 1983 | C1062: Jul | D1062: 25 | E1062: 5 | F1062: 8596.83 | G1062: tier - 2 | H1062: tier - 3 | I1062: R1013 | J1062: =DATE(B1062,MONTH(1&C1062),D1062) -> 30522
A1063: Id1277 | B1063: 1973 | C1063: Jul | D1063: 11 | E1063: 0 | F1063: 8601.33 | G1063: tier - 2 | H1063: tier - 1 | I1063: R1013 | J1063: =DATE(B1063,MONTH(1&C1063),D1063) -> 26856
A1064: Id1276 | B1064: 1977 | C1064: Sep | D1064: 24 | E1064: 2 | F1064: 8603.82 | G1064: tier - 2 | H1064: tier - 1 | I1064: R1019 | J1064: =DATE(B1064,MONTH(1&C1064),D1064) -> 28392
A1065: Id1275 | B1065: 1977 | C1065: Nov | D1065: 12 | E1065: 2 | F1065: 8604.48 | G1065: tier - 3 | H1065: tier - 2 | I1065: R1016 | J1065: =DATE(B1065,MONTH(1&C1065),D1065) -> 28441
A1066: Id1274 | B1066: 1977 | C1066: Oct | D1066: 15 | E1066: 3 | F1066: 8605.36 | G1066: tier - 2 | H1066: tier - 2 | I1066: R1013 | J1066: =DATE(B1066,MONTH(1&C1066),D1066) -> 28413
... A2344: Id1 | B2344: 1968 | C2344: Oct | D2344: 12 | E2344: 0 | F2344: 63770.43 | G2344: tier - 1 | H2344: tier - 3 | I2344: R1013 | J2344: =DATE(B2344,MONTH(1&C2344),D2344) -> 25123
A2345: FIRST ANS:
A2346: =COUNTIF(A2:A2344,"~?") -> 6 | B2346: =COUNTIF(B2:B2344,"~?") -> 2 | C2346: =COUNTIF(C2:C2344,"~?") -> 0 | D2346: =COUNTIF(D2:D2344,"~?") -> 0 | E2346: =COUNTIF(E2:E2344,"~?") -> 0 | F2346: =COUNTIF(F2:F2344,"~?") -> 0 | G2346: =COUNTIF(G2:G2344,"~?") -> 0 | H2346: =COUNTIF(H2:H2344,"~?") -> 0 | I2346: =COUNTIF(I2:I2344,"~?") -> 2
A2349: 2 ND ANS:
B2350: =ROUND(AVERAGE(B2:B2344),0) -> 1983
A2352: 3 rd ANS:
F2354: tier -1 | G2354: =COUNTIF(G2:G2344,"tier - 1") -> 309 | H2354: =COUNTIF(H2:H2344,"tier - 1") -> 734
F2355: tier - 2 | G2355: =COUNTIF(G2:G2344,"tier - 2") -> 1340 | H2355: =COUNTIF(H2:H2344,"tier - 2") -> 813
F2356: tier - 3 | G2356: =COUNTIF(G2:G2344,"tier - 3") -> 694 | H2356: =COUNTIF(H2:H2344,"tier - 3") -> 796
A2360: 4 th ANS: | B2360: NO MISSING VALUES

Sheet Health care
A1: Customer ID | B1: name | C1: Health care | D1: HBA1C | E1: Heart Issues | F1: Any Transplants | G1: Cancer history | H1: NumberOfMajorSurgeries | I1: smoker | J1: Weight Status | K1: Diabetes Status | L1: date | M1: month | N1: year | O1: YYY-MM-DD | P1: charges | Q1: Hospital tier | R1: City tier | S1: State ID | T1: Age | U1: VLOOKUP
A2: Id1 | B2: Hawks, | C2: 47.41 | D2: 7.47 | E2: No | F2: No | G2: No | H2: 0 | I2: Yes | J2: =IF(C2<18.5,"Under Weight",IF(C2<25,"Normal Weight",IF(C2<30,"Over weight","Obesity"))) -> Obesity | K2: =IF(D2<5.7,"Normal",IF(D2<6.5,"Prediabetes","Diabetes")) -> Diabetes | L2: 9 | M2: Jul | N2: 1992 | O2: =DATE(N2,MONTH(1&M2),L2) -> 33794 | P2: 563.84 | Q2: tier - 2 | R2: tier - 3 | S2: R1013 | T2: =YEAR(TODAY())-YEAR(O2) -> 34 | U2: =VLOOKUP($A2,'Medical Examination'!$A:$Z,2,FALSE) -> 47.41
A3: Id2 | B3: Lehner, | C3: 30.36 | D3: 5.77 | E3: No | F3: No | G3: No | H3: 0 | I3: Yes | J3: =IF(C3<18.5,"Under Weight",IF(C3<25,"Normal Weight",IF(C3<30,"Over weight","Obesity"))) -> Obesity | K3: =IF(D3<5.7,"Normal",IF(D3<6.5,"Prediabetes","Diabetes")) -> Prediabetes | L3: 30 | M3: Nov | N3: 1992 | O3: =DATE(N3,MONTH(1&M3),L3) -> 33938 | P3: 570.62 | Q3: tier - 2 | R3: tier - 1 | S3: R1013 | T3: =YEAR(TODAY())-YEAR(O3) -> 34 | U3: =VLOOKUP($A3,'Medical Examination'!$A:$Z,2,FALSE) -> 30.36
A4: Id3 | B4: Lu, | C4: 34.485 | D4: 11.87 | E4: Yes | F4: No | G4: No | H4: 1 | I4: Yes | J4: =IF(C4<18.5,"Under Weight",IF(C4<25,"Normal Weight",IF(C4<30,"Over weight","Obesity"))) -> Obesity | K4: =IF(D4<5.7,"Normal",IF(D4<6.5,"Prediabetes","Diabetes")) -> Diabetes | L4: 30 | M4: Jun | N4: 1993 | O4: =DATE(N4,MONTH(1&M4),L4) -> 34150 | P4: 600 | Q4: tier - 2 | R4: tier - 1 | S4: R1013 | T4: =YEAR(TODAY())-YEAR(O4) -> 33 | U4: =VLOOKUP($A4,'Medical Examination'!$A:$Z,2,FALSE) -> 34.485
A5: Id4 | B5: Osborne, | C5: 38.095 | D5: 6.05 | E5: No | F5: No | G5: No | H5: 0 | I5: Yes | J5: =IF(C5<18.5,"Under Weight",IF(C5<25,"Normal Weight",IF(C5<30,"Over weight","Obesity"))) -> Obesity | K5: =IF(D5<5.7,"Normal",IF(D5<6.5,"Prediabetes","Diabetes")) -> Prediabetes | L5: 13 | M5: Sep | N5: 1992 | O5: =DATE(N5,MONTH(1&M5),L5) -> 33860 | P5: 604.54 | Q5: tier - 3 | R5: tier - 3 | S5: R1013 | T5: =YEAR(TODAY())-YEAR(O5) -> 34 | U5: =VLOOKUP($A5,'Medical Examination'!$A:$Z,2,FALSE) -> 38.095
A6: Id5 | B6: Kadala, | C6: 35.53 | D6: 5.45 | E6: No | F6: No | G6: No | H6: 0 | I6: Yes | J6: =IF(C6<18.5,"Under Weight",IF(C6<25,"Normal Weight",IF(C6<30,"Over weight","Obesity"))) -> Obesity | K6: =IF(D6<5.7,"Normal",IF(D6<6.5,"Prediabetes","Diabetes")) -> Normal | L6: 27 | M6: Jul | N6: 1998 | O6: =DATE(N6,MONTH(1&M6),L6) -> 36003 | P6: 637.26 | Q6: tier - 3 | R6: tier - 3 | S6: R1013 | T6: =YEAR(TODAY())-YEAR(O6) -> 28 | U6: =VLOOKUP($A6,'Medical Examination'!$A:$Z,2,FALSE) -> 35.53
A7: Id6 | B7: Baker, | C7: 32.8 | D7: 6.59 | E7: No | F7: No | G7: No | H7: 0 | I7: Yes | J7: =IF(C7<18.5,"Under Weight",IF(C7<25,"Normal Weight",IF(C7<30,"Over weight","Obesity"))) -> Obesity | K7: =IF(D7<5.7,"Normal",IF(D7<6.5,"Prediabetes","Diabetes")) -> Diabetes | L7: 20 | M7: Nov | N7: 2001 | O7: =DATE(N7,MONTH(1&M7),L7) -> 37215 | P7: 646.14 | Q7: tier - 3 | R7: tier - 3 | S7: R1012 | T7: =YEAR(TODAY())-YEAR(O7) -> 25 | U7: =VLOOKUP($A7,'Medical Examination'!$A:$Z,2,FALSE) -> 32.8
A8: Id7 | B8: Macpherson, | C8: 36.4 | D8: 6.07 | E8: No | F8: No | G8: No | H8: 0 | I8: Yes | J8: =IF(C8<18.5,"Under Weight",IF(C8<25,"Normal Weight",IF(C8<30,"Over weight","Obesity"))) -> Obesity | K8: =IF(D8<5.7,"Normal",IF(D8<6.5,"Prediabetes","Diabetes")) -> Prediabetes | L8: 1 | M8: Jun | N8: 1993 | O8: =DATE(N8,MONTH(1&M8),L8) -> 34121 | P8: 650 | Q8: tier - 3 | R8: tier - 3 | S8: R1013 | T8: =YEAR(TODAY())-YEAR(O8) -> 33 | U8: =VLOOKUP($A8,'Medical Examination'!$A:$Z,2,FALSE) -> 36.4
A9: Id8 | B9: Hallman, | C9: 36.96 | D9: 7.93 | E9: No | F9: No | G9: No | H9: 1 | I9: Yes | J9: =IF(C9<18.5,"Under Weight",IF(C9<25,"Normal Weight",IF(C9<30,"Over weight","Obesity"))) -> Obesity | K9: =IF(D9<5.7,"Normal",IF(D9<6.5,"Prediabetes","Diabetes")) -> Diabetes | L9: 4 | M9: Jul | N9: 1995 | O9: =DATE(N9,MONTH(1&M9),L9) -> 34884 | P9: 650 | Q9: tier - 3 | R9: tier - 3 | S9: R1013 | T9: =YEAR(TODAY())-YEAR(O9) -> 31 | U9: =VLOOKUP($A9,'Medical Examination'!$A:$Z,2,FALSE) -> 36.96
A10: Id9 | B10: Moran, | C10: 41.14 | D10: 9.58 | E10: Yes | F10: No | G10: Yes | H10: 1 | I10: Yes | J10: =IF(C10<18.5,"Under Weight",IF(C10<25,"Normal Weight",IF(C10<30,"Over weight","Obesity"))) -> Obesity | K10: =IF(D10<5.7,"Normal",IF(D10<6.5,"Prediabetes","Diabetes")) -> Diabetes | L10: 29 | M10: Nov | N10: 2002 | O10: =DATE(N10,MONTH(1&M10),L10) -> 37589 | P10: 668 | Q10: tier - 3 | R10: tier - 2 | S10: R1012 | T10: =YEAR(TODAY())-YEAR(O10) -> 24 | U10: =VLOOKUP($A10,'Medical Examination'!$A:$Z,2,FALSE) -> 41.14
A11: Id10 | B11: Benner, | C11: 38.06 | D11: 10.79 | E11: No | F11: No | G11: No | H11: 0 | I11: Yes | J11: =IF(C11<18.5,"Under Weight",IF(C11<25,"Normal Weight",IF(C11<30,"Over weight","Obesity"))) -> Obesity | K11: =IF(D11<5.7,"Normal",IF(D11<6.5,"Prediabetes","Diabetes")) -> Diabetes | L11: 9 | M11: Nov | N11: 1997 | O11: =DATE(N11,MONTH(1&M11),L11) -> 35743 | P11: 670 | Q11: tier - 3 | R11: tier - 3 | S11: R1013 | T11: =YEAR(TODAY())-YEAR(O11) -> 29 | U11: =VLOOKUP($A11,'Medical Examination'!$A:$Z,2,FALSE) -> 38.06
A12: Id11 | B12: Fierro | C12: 37.7 | D12: 5.96 | E12: Yes | F12: No | G12: No | H12: 1 | I12: Yes | J12: =IF(C12<18.5,"Under Weight",IF(C12<25,"Normal Weight",IF(C12<30,"Over weight","Obesity"))) -> Obesity | K12: =IF(D12<5.7,"Normal",IF(D12<6.5,"Prediabetes","Diabetes")) -> Prediabetes | L12: 12 | M12: Sep | N12: 2001 | O12: =DATE(N12,MONTH(1&M12),L12) -> 37146 | P12: 687.54 | Q12: tier - 3 | R12: tier - 2 | S12: R1013 | T12: =YEAR(TODAY())-YEAR(O12) -> 25 | U12: =VLOOKUP($A12,'Medical Examination'!$A:$Z,2,FALSE) -> 37.7
A13: Id12 | B13: Franz, | C13: 42.13 | D13: 11.9 | E13: No | F13: No | G13: No | H13: 0 | I13: Yes | J13: =IF(C13<18.5,"Under Weight",IF(C13<25,"Normal Weight",IF(C13<30,"Over weight","Obesity"))) -> Obesity | K13: =IF(D13<5.7,"Normal",IF(D13<6.5,"Prediabetes","Diabetes")) -> Diabetes | L13: 26 | M13: Dec | N13: 1999 | O13: =DATE(N13,MONTH(1&M13),L13) -> 36520 | P13: 700 | Q13: tier - 2 | R13: tier - 3 | S13: R1013 | T13: =YEAR(TODAY())-YEAR(O13) -> 27 | U13: =VLOOKUP($A13,'Medical Examination'!$A:$Z,2,FALSE) -> 42.13
... A101: Id100 | B101: Gollins, | C101: 48.2 | D101: 4.84 | E101: No | F101: No | G101: No | H101: 0 | I101: Yes | J101: =IF(C101<18.5,"Under Weight",IF(C101<25,"Normal Weight",IF(C101<30,"Over weight","Obesity"))) -> Obesity | K101: =IF(D101<5.7,"Normal",IF(D101<6.5,"Prediabetes","Diabetes")) -> Normal | L101: 22 | M101: Dec | N101: 2002 | O101: =DATE(N101,MONTH(1&M101),L101) -> 37612 | P101: 1391.53 | Q101: tier - 2 | R101: tier - 1 | S101: R1013 | T101: =YEAR(TODAY())-YEAR(O101) -> 24 | U101: =VLOOKUP($A101,'Medical Examination'!$A:$Z,2,FALSE) -> 48.2
A102: Id101 | B102: Benestad, | C102: 35.75 | D102: Yes | E102: Yes | F102: No | G102: No | H102: 0 | I102: Yes | J102: =IF(C102<18.5,"Under Weight",IF(C102<25,"Normal Weight",IF(C102<30,"Over weight","Obesity"))) -> Obesity | K102: =IF(D102<5.7,"Normal",IF(D102<6.5,"Prediabetes","Diabetes")) -> Diabetes | L102: 5 | M102: Sep | N102: 1998 | O102: =DATE(N102,MONTH(1&M102),L102) -> 36043 | P102: 1400.44 | Q102: tier - 2 | R102: tier - 2 | S102: R1013 | T102: =YEAR(TODAY())-YEAR(O102) -> 28 | U102: =VLOOKUP($A102,'Medical Examination'!$A:$Z,2,FALSE) -> 35.75
A103: Id102 | B103: Aviv, | C103: 53.81 | D103: 8.77 | E103: Yes | F103: No | G103: No | H103: 0 | I103: Yes | J103: =IF(C103<18.5,"Under Weight",IF(C103<25,"Normal Weight",IF(C103<30,"Over weight","Obesity"))) -> Obesity | K103: =IF(D103<5.7,"Normal",IF(D103<6.5,"Prediabetes","Diabetes")) -> Diabetes | L103: 27 | M103: Oct | N103: 1997 | O103: =DATE(N103,MONTH(1&M103),L103) -> 35730 | P103: 1402 | Q103: tier - 2 | R103: tier - 3 | S103: R1011 | T103: =YEAR(TODAY())-YEAR(O103) -> 29 | U103: =VLOOKUP($A103,'Medical Examination'!$A:$Z,2,FALSE) -> 53.81
A104: Id103 | B104: Burns, | C104: 49.48 | D104: 4.96 | E104: No | F104: No | G104: Yes | H104: 1 | I104: Yes | J104: =IF(C104<18.5,"Under Weight",IF(C104<25,"Normal Weight",IF(C104<30,"Over weight","Obesity"))) -> Obesity | K104: =IF(D104<5.7,"Normal",IF(D104<6.5,"Prediabetes","Diabetes")) -> Normal | L104: 23 | M104: Jun | N104: 1996 | O104: =DATE(N104,MONTH(1&M104),L104) -> 35239 | P104: 1417 | Q104: tier - 2 | R104: tier - 3 | S104: R1013 | T104: =YEAR(TODAY())-YEAR(O104) -> 30 | U104: =VLOOKUP($A104,'Medical Examination'!$A:$Z,2,FALSE) -> 49.48
A105: Id104 | B105: Maldonado, | C105: 34.1 | D105: 4.43 | E105: Yes | F105: No | G105: No | H105: 0 | I105: Yes | J105: =IF(C105<18.5,"Under Weight",IF(C105<25,"Normal Weight",IF(C105<30,"Over weight","Obesity"))) -> Obesity | K105: =IF(D105<5.7,"Normal",IF(D105<6.5,"Prediabetes","Diabetes")) -> Normal | L105: 23 | M105: Aug | N105: 2001 | O105: =DATE(N105,MONTH(1&M105),L105) -> 37126 | P105: 1421 | Q105: tier - 2 | R105: tier - 2 | S105: R1013 | T105: =YEAR(TODAY())-YEAR(O105) -> 25 | U105: =VLOOKUP($A105,'Medical Examination'!$A:$Z,2,FALSE) -> 34.1
A106: Id105 | B106: Yitref, | C106: 35.3 | D106: 5.82 | E106: Yes | F106: No | G106: Yes | H106: 1 | I106: Yes | J106: =IF(C106<18.5,"Under Weight",IF(C106<25,"Normal Weight",IF(C106<30,"Over weight","Obesity"))) -> Obesity | K106: =IF(D106<5.7,"Normal",IF(D106<6.5,"Prediabetes","Diabetes")) -> Prediabetes | L106: 5 | M106: Dec | N106: 1997 | O106: =DATE(N106,MONTH(1&M106),L106) -> 35769 | P106: 1422 | Q106: tier - 2 | R106: tier - 2 | S106: R1013 | T106: =YEAR(TODAY())-YEAR(O106) -> 29 | U106: =VLOOKUP($A106,'Medical Examination'!$A:$Z,2,FALSE) -> 35.3
A107: Id106 | B107: Loudon-Brown, | C107: 43.83 | D107: 6.03 | E107: Yes | F107: No | G107: No | H107: 1 | I107: Yes | J107: =IF(C107<18.5,"Under Weight",IF(C107<25,"Normal Weight",IF(C107<30,"Over weight","Obesity"))) -> Obesity | K107: =IF(D107<5.7,"Normal",IF(D107<6.5,"Prediabetes","Diabetes")) -> Prediabetes | L107: 1 | M107: Sep | N107: 2000 | O107: =DATE(N107,MONTH(1&M107),L107) -> 36770 | P107: 1438 | Q107: tier - 2 | R107: tier - 2 | S107: R1013 | T107: =YEAR(TODAY())-YEAR(O107) -> 26 | U107: =VLOOKUP($A107,'Medical Examination'!$A:$Z,2,FALSE) -> 43.83
A108: Id107 | B108: Sugathadasa, | C108: 50.07 | D108: 9.27 | E108: No | F108: No | G108: No | H108: 0 | I108: Yes | J108: =IF(C108<18.5,"Under Weight",IF(C108<25,"Normal Weight",IF(C108<30,"Over weight","Obesity"))) -> Obesity | K108: =IF(D108<5.7,"Normal",IF(D108<6.5,"Prediabetes","Diabetes")) -> Diabetes | L108: 19 | M108: Jun | N108: 1997 | O108: =DATE(N108,MONTH(1&M108),L108) -> 35600 | P108: 1445 | Q108: tier - 2 | R108: tier - 1 | S108: R1013 | T108: =YEAR(TODAY())-YEAR(O108) -> 29 | U108: =VLOOKUP($A108,'Medical Examination'!$A:$Z,2,FALSE) -> 50.07
A109: Id108 | B109: Ganley, | C109: 32.775 | D109: 5.53 | E109: No | F109: No | G109: No | H109: 0 | I109: Yes | J109: =IF(C109<18.5,"Under Weight",IF(C109<25,"Normal Weight",IF(C109<30,"Over weight","Obesity"))) -> Obesity | K109: =IF(D109<5.7,"Normal",IF(D109<6.5,"Prediabetes","Diabetes")) -> Normal | L109: 20 | M109: Jun | N109: 2003 | O109: =DATE(N109,MONTH(1&M109),L109) -> 37792 | P109: 1467 | Q109: tier - 2 | R109: tier - 2 | S109: R1013 | T109: =YEAR(TODAY())-YEAR(O109) -> 23 | U109: =VLOOKUP($A109,'Medical Examination'!$A:$Z,2,FALSE) -> 32.775
A110: Id109 | B110: Potter, | C110: 34.105 | D110: 5.07 | E110: No | F110: No | G110: No | H110: 1 | I110: Yes | J110: =IF(C110<18.5,"Under Weight",IF(C110<25,"Normal Weight",IF(C110<30,"Over weight","Obesity"))) -> Obesity | K110: =IF(D110<5.7,"Normal",IF(D110<6.5,"Prediabetes","Diabetes")) -> Normal | L110: 7 | M110: Dec | N110: 1998 | O110: =DATE(N110,MONTH(1&M110),L110) -> 36136 | P110: 1477 | Q110: tier - 2 | R110: tier - 1 | S110: R1013 | T110: =YEAR(TODAY())-YEAR(O110) -> 28 | U110: =VLOOKUP($A110,'Medical Examination'!$A:$Z,2,FALSE) -> 34.105
A111: Id110 | B111: Rasmussen, | C111: 48.93 | D111: 11.17 | E111: Yes | F111: No | G111: No | H111: 1 | I111: Yes | J111: =IF(C111<18.5,"Under Weight",IF(C111<25,"Normal Weight",IF(C111<30,"Over weight","Obesity"))) -> Obesity | K111: =IF(D111<5.7,"Normal",IF(D111<6.5,"Prediabetes","Diabetes")) -> Diabetes | L111: 9 | M111: Jun | N111: 1997 | O111: =DATE(N111,MONTH(1&M111),L111) -> 35590 | P111: 1481 | Q111: tier - 2 | R111: tier - 1 | S111: R1012 | T111: =YEAR(TODAY())-YEAR(O111) -> 29 | U111: =VLOOKUP($A111,'Medical Examination'!$A:$Z,2,FALSE) -> 48.93
A112: Id111 | B112: Robinson, | C112: 37.07 | D112: 6.14 | E112: Yes | F112: No | G112: No | H112: 0 | I112: Yes | J112: =IF(C112<18.5,"Under Weight",IF(C112<25,"Normal Weight",IF(C112<30,"Over weight","Obesity"))) -> Obesity | K112: =IF(D112<5.7,"Normal",IF(D112<6.5,"Prediabetes","Diabetes")) -> Prediabetes | L112: 7 | M112: Oct | N112: 1995 | O112: =DATE(N112,MONTH(1&M112),L112) -> 34979 | P112: 1493 | Q112: tier - 2 | R112: tier - 3 | S112: R1013 | T112: =YEAR(TODAY())-YEAR(O112) -> 31 | U112: =VLOOKUP($A112,'Medical Examination'!$A:$Z,2,FALSE) -> 37.07
A113: Id112 | B113: Antonopoulos, | C113: 51.51 | D113: 6.26 | E113: Yes | F113: No | G113: Yes | H113: 1 | I113: Yes | J113: =IF(C113<18.5,"Under Weight",IF(C113<25,"Normal Weight",IF(C113<30,"Over weight","Obesity"))) -> Obesity | K113: =IF(D113<5.7,"Normal",IF(D113<6.5,"Prediabetes","Diabetes")) -> Prediabetes | L113: 19 | M113: Jun | N113: 1998 | O113: =DATE(N113,MONTH(1&M113),L113) -> 35965 | P113: 1497 | Q113: tier - 2 | R113: tier - 2 | S113: R1013 | T113: =YEAR(TODAY())-YEAR(O113) -> 28 | U113: =VLOOKUP($A113,'Medical Examination'!$A:$Z,2,FALSE) -> 51.51
A114: Id113 | B114: Groner, | C114: 34.8 | D114: 4.72 | E114: Yes | F114: No | G114: No | H114: 0 | I114: Yes | J114: =IF(C114<18.5,"Under Weight",IF(C114<25,"Normal Weight",IF(C114<30,"Over weight","Obesity"))) -> Obesity | K114: =IF(D114<5.7,"Normal",IF(D114<6.5,"Prediabetes","Diabetes")) -> Normal | L114: 25 | M114: Aug | N114: 2001 | O114: =DATE(N114,MONTH(1&M114),L114) -> 37128 | P114: 1515.34 | Q114: tier - 2 | R114: tier - 3 | S114: R1013 | T114: =YEAR(TODAY())-YEAR(O114) -> 25 | U114: =VLOOKUP($A114,'Medical Examination'!$A:$Z,2,FALSE) -> 34.8
... A167: Id166 | B167: Wittmann, | C167: 37.87 | D167: 4.29 | E167: Yes | F167: No | G167: Yes | H167: 1 | I167: Yes | J167: =IF(C167<18.5,"Under Weight",IF(C167<25,"Normal Weight",IF(C167<30,"Over weight","Obesity"))) -> Obesity | K167: =IF(D167<5.7,"Normal",IF(D167<6.5,"Prediabetes","Diabetes")) -> Normal | L167: 19 | M167: Aug | N167: 2004 | O167: =DATE(N167,MONTH(1&M167),L167) -> 38218 | P167: 1822.54 | Q167: tier - 3 | R167: tier - 1 | S167: R1012 | T167: =YEAR(TODAY())-YEAR(O167) -> 22 | U167: =VLOOKUP($A167,'Medical Examination'!$A:$Z,2,FALSE) -> 37.87
A168: Id167 | B168: Tremblay, | C168: 40.61 | D168: Yes | E168: Yes | F168: No | G168: No | H168: 1 | I168: Yes | J168: =IF(C168<18.5,"Under Weight",IF(C168<25,"Normal Weight",IF(C168<30,"Over weight","Obesity"))) -> Obesity | K168: =IF(D168<5.7,"Normal",IF(D168<6.5,"Prediabetes","Diabetes")) -> Diabetes | L168: 17 | M168: Nov | N168: 1999 | O168: =DATE(N168,MONTH(1&M168),L168) -> 36481 | P168: 1824.29 | Q168: tier - 3 | R168: tier - 3 | S168: R1013 | T168: =YEAR(TODAY())-YEAR(O168) -> 27 | U168: =VLOOKUP($A168,'Medical Examination'!$A:$Z,2,FALSE) -> 40.61
A169: Id168 | B169: Scofield, | C169: 30.78 | D169: 4.67 | E169: Yes | F169: No | G169: No | H169: 0 | I169: Yes | J169: =IF(C169<18.5,"Under Weight",IF(C169<25,"Normal Weight",IF(C169<30,"Over weight","Obesity"))) -> Obesity | K169: =IF(D169<5.7,"Normal",IF(D169<6.5,"Prediabetes","Diabetes")) -> Normal | L169: 1 | M169: Oct | N169: 1999 | O169: =DATE(N169,MONTH(1&M169),L169) -> 36434 | P169: 1826.84 | Q169: tier - 3 | R169: tier - 2 | S169: R1011 | T169: =YEAR(TODAY())-YEAR(O169) -> 27 | U169: =VLOOKUP($A169,'Medical Examination'!$A:$Z,2,FALSE) -> 30.78
A170: Id169 | B170: Yost, | C170: 49.49 | D170: 4.5 | E170: No | F170: No | G170: No | H170: 0 | I170: Yes | J170: =IF(C170<18.5,"Under Weight",IF(C170<25,"Normal Weight",IF(C170<30,"Over weight","Obesity"))) -> Obesity | K170: =IF(D170<5.7,"Normal",IF(D170<6.5,"Prediabetes","Diabetes")) -> Normal | L170: 11 | M170: Aug | N170: 2003 | O170: =DATE(N170,MONTH(1&M170),L170) -> 37844 | P170: 1832.09 | Q170: tier - 3 | R170: tier - 3 | S170: R1011 | T170: =YEAR(TODAY())-YEAR(O170) -> 23 | U170: =VLOOKUP($A170,'Medical Examination'!$A:$Z,2,FALSE) -> 49.49
A171: Id170 | B171: Torphy, | C171: 37.62 | D171: 6.32 | E171: Yes | F171: yes | G171: No | H171: 1 | I171: Yes | J171: =IF(C171<18.5,"Under Weight",IF(C171<25,"Normal Weight",IF(C171<30,"Over weight","Obesity"))) -> Obesity | K171: =IF(D171<5.7,"Normal",IF(D171<6.5,"Prediabetes","Diabetes")) -> Prediabetes | L171: 4 | M171: Aug | N171: 2003 | O171: =DATE(N171,MONTH(1&M171),L171) -> 37837 | P171: 1837.24 | Q171: tier - 3 | R171: tier - 2 | S171: R1011 | T171: =YEAR(TODAY())-YEAR(O171) -> 23 | U171: =VLOOKUP($A171,'Medical Examination'!$A:$Z,2,FALSE) -> 37.62
A172: Id171 | B172: Busby, | C172: 36.08 | D172: 6.1 | E172: Yes | F172: No | G172: No | H172: 1 | I172: Yes | J172: =IF(C172<18.5,"Under Weight",IF(C172<25,"Normal Weight",IF(C172<30,"Over weight","Obesity"))) -> Obesity | K172: =IF(D172<5.7,"Normal",IF(D172<6.5,"Prediabetes","Diabetes")) -> Prediabetes | L172: 12 | M172: Dec | N172: 1999 | O172: =DATE(N172,MONTH(1&M172),L172) -> 36506 | P172: 1837.28 | Q172: tier - 3 | R172: tier - 2 | S172: R1013 | T172: =YEAR(TODAY())-YEAR(O172) -> 27 | U172: =VLOOKUP($A172,'Medical Examination'!$A:$Z,2,FALSE) -> 36.08
A173: Id172 | B173: Nguyen, | C173: 33.5 | D173: 5.4 | E173: No | F173: No | G173: No | H173: 0 | I173: Yes | J173: =IF(C173<18.5,"Under Weight",IF(C173<25,"Normal Weight",IF(C173<30,"Over weight","Obesity"))) -> Obesity | K173: =IF(D173<5.7,"Normal",IF(D173<6.5,"Prediabetes","Diabetes")) -> Normal | L173: 20 | M173: Jul | N173: 2003 | O173: =DATE(N173,MONTH(1&M173),L173) -> 37822 | P173: 1842.52 | Q173: tier - 3 | R173: tier - 2 | S173: R1011 | T173: =YEAR(TODAY())-YEAR(O173) -> 23 | U173: =VLOOKUP($A173,'Medical Examination'!$A:$Z,2,FALSE) -> 33.5
A174: Id173 | B174: Hanley, | C174: 47.46 | D174: 6.24 | E174: Yes | F174: No | G174: No | H174: 1 | I174: Yes | J174: =IF(C174<18.5,"Under Weight",IF(C174<25,"Normal Weight",IF(C174<30,"Over weight","Obesity"))) -> Obesity | K174: =IF(D174<5.7,"Normal",IF(D174<6.5,"Prediabetes","Diabetes")) -> Prediabetes | L174: 6 | M174: Dec | N174: 1994 | O174: =DATE(N174,MONTH(1&M174),L174) -> 34674 | P174: 1850.55 | Q174: tier - 3 | R174: tier - 2 | S174: R1012 | T174: =YEAR(TODAY())-YEAR(O174) -> 32 | U174: =VLOOKUP($A174,'Medical Examination'!$A:$Z,2,FALSE) -> 47.46
A175: Id174 | B175: Scheer, | C175: 49.24 | D175: 4.45 | E175: No | F175: No | G175: No | H175: 0 | I175: Yes | J175: =IF(C175<18.5,"Under Weight",IF(C175<25,"Normal Weight",IF(C175<30,"Over weight","Obesity"))) -> Obesity | K175: =IF(D175<5.7,"Normal",IF(D175<6.5,"Prediabetes","Diabetes")) -> Normal | L175: 27 | M175: Dec | N175: 2004 | O175: =DATE(N175,MONTH(1&M175),L175) -> 38348 | P175: 1863.45 | Q175: tier - 3 | R175: tier - 1 | S175: R1025 | T175: =YEAR(TODAY())-YEAR(O175) -> 22 | U175: =VLOOKUP($A175,'Medical Examination'!$A:$Z,2,FALSE) -> 49.24
A176: Id175 | B176: Rankin, | C176: 54.4 | D176: 5.22 | E176: No | F176: No | G176: No | H176: 1 | I176: Yes | J176: =IF(C176<18.5,"Under Weight",IF(C176<25,"Normal Weight",IF(C176<30,"Over weight","Obesity"))) -> Obesity | K176: =IF(D176<5.7,"Normal",IF(D176<6.5,"Prediabetes","Diabetes")) -> Normal | L176: 2 | M176: Jul | N176: 1996 | O176: =DATE(N176,MONTH(1&M176),L176) -> 35248 | P176: 1865.98 | Q176: tier - 3 | R176: tier - 3 | S176: R1012 | T176: =YEAR(TODAY())-YEAR(O176) -> 30 | U176: =VLOOKUP($A176,'Medical Examination'!$A:$Z,2,FALSE) -> 54.4
A177: Id176 | B177: Ricardi, | C177: 35.53 | D177: 4.61 | E177: No | F177: No | G177: No | H177: 1 | I177: Yes | J177: =IF(C177<18.5,"Under Weight",IF(C177<25,"Normal Weight",IF(C177<30,"Over weight","Obesity"))) -> Obesity | K177: =IF(D177<5.7,"Normal",IF(D177<6.5,"Prediabetes","Diabetes")) -> Normal | L177: 22 | M177: Sep | N177: 2002 | O177: =DATE(N177,MONTH(1&M177),L177) -> 37521 | P177: 1875.34 | Q177: tier - 3 | R177: tier - 2 | S177: R1011 | T177: =YEAR(TODAY())-YEAR(O177) -> 24 | U177: =VLOOKUP($A177,'Medical Examination'!$A:$Z,2,FALSE) -> 35.53
A178: Id177 | B178: Karkos, | C178: 39.73 | D178: 6.24 | E178: No | F178: No | G178: No | H178: 0 | I178: Yes | J178: =IF(C178<18.5,"Under Weight",IF(C178<25,"Normal Weight",IF(C178<30,"Over weight","Obesity"))) -> Obesity | K178: =IF(D178<5.7,"Normal",IF(D178<6.5,"Prediabetes","Diabetes")) -> Prediabetes | L178: 29 | M178: Oct | N178: 2002 | O178: =DATE(N178,MONTH(1&M178),L178) -> 37558 | P178: 1877.93 | Q178: tier - 3 | R178: tier - 1 | S178: R1013 | T178: =YEAR(TODAY())-YEAR(O178) -> 24 | U178: =VLOOKUP($A178,'Medical Examination'!$A:$Z,2,FALSE) -> 39.73
A179: Id178 | B179: Price-Dierksen, | C179: 35.68 | D179: 10.04 | E179: No | F179: No | G179: No | H179: 0 | I179: Yes | J179: =IF(C179<18.5,"Under Weight",IF(C179<25,"Normal Weight",IF(C179<30,"Over weight","Obesity"))) -> Obesity | K179: =IF(D179<5.7,"Normal",IF(D179<6.5,"Prediabetes","Diabetes")) -> Diabetes | L179: 29 | M179: Aug | N179: 2002 | O179: =DATE(N179,MONTH(1&M179),L179) -> 37497 | P179: 1880.07 | Q179: tier - 3 | R179: tier - 2 | S179: R1013 | T179: =YEAR(TODAY())-YEAR(O179) -> 24 | U179: =VLOOKUP($A179,'Medical Examination'!$A:$Z,2,FALSE) -> 35.68
...

Sheet Analysis pie and donut
B3: Column Labels
B4: No | D4: Yes | F4: Total Average of HBA1C | G4: Total Sum of NumberOfMajorSurgeries
A5: Row Labels | B5: Average of HBA1C | C5: Sum of NumberOfMajorSurgeries | D5: Average of HBA1C | E5: Sum of NumberOfMajorSurgeries
A6: No | B6: 6.8799553 | C6: 726 | D6: 5.7391688 | E6: 391 | F6: 6.6778371 | G6: 1117
A7: No | B7: 6.8636074 | C7: 564 | D7: 5.7818272 | E7: 307 | F7: 6.6734112 | G7: 871
A8: Yes | B8: 6.9411406 | C8: 162 | D8: 5.5863095 | E8: 84 | F8: 6.6942733 | G8: 246
A9: yes | B9: 5.181958 | C9: 144 | F9: 5.181958 | G9: 144
A10: No | B10: 5.2091453 | C10: 118 | F10: 5.2091453 | G10: 118
A11: Yes | B11: 5.0596154 | C11: 26 | F11: 5.0596154 | G11: 26
A12: Grand Total | B12: 6.7542103 | C12: 870 | D12: 5.7391688 | E12: 391 | F12: 6.585475 | G12: 1261

Sheet Column and Bar chart
B3: Column Labels
B4: No | F4: Yes | J4: Total Count of HBA1C | K4: Total Average of HBA1C | L4: Total Sum of NumberOfMajorSurgeries2 | M4: Total Sum of NumberOfMajorSurgeries
A5: Row Labels | B5: Count of HBA1C | C5: Average of HBA1C | D5: Sum of NumberOfMajorSurgeries2 | E5: Sum of NumberOfMajorSurgeries | F5: Count of HBA1C | G5: Average of HBA1C | H5: Sum of NumberOfMajorSurgeries2 | I5: Sum of NumberOfMajorSurgeries
A6: No | B6: 1800 | C6: 6.8799553 | D6: 726 | E6: 726 | F6: 391 | G6: 5.7391688 | H6: 391 | I6: 391 | J6: 2191 | K6: 6.6778371 | L6: 1117 | M6: 1117
A7: yes | B7: 144 | C7: 5.181958 | D7: 144 | E7: 144 | J7: 144 | K7: 5.181958 | L7: 144 | M7: 144
A8: Grand Total | B8: 1944 | C8: 6.7542103 | D8: 870 | E8: 870 | F8: 391 | G8: 5.7391688 | H8: 391 | I8: 391 | J8: 2335 | K8: 6.585475 | L8: 1261 | M8: 1261

Sheet Weight and Diabetes
A3: Average of charges | B3: Column Labels
A4: Row Labels | B4: Diabetes | C4: Normal | D4: Prediabetes | E4: Grand Total
A5: Normal Weight | B5: 11718.429 | C5: 20473.459 | D5: 18727.774 | E5: 17284.97
A6: Obesity | B6: 7265.8143 | C6: 12283.886 | D6: 12070.354 | E6: 10483.967
A7: Over weight | B7: 9369.4914 | C7: 15322.339 | D7: 16497.218 | E7: 13662.615
A8: Under Weight | B8: 17912.901 | C8: 26863.078 | D8: 25824.313 | E8: 23386.455
A9: Grand Total | B9: 9358.0057 | C9: 15640.05 | D9: 15203.578 | E9: 13411.324

Sheet Age vs BMI
